<?xml version="1.0" encoding="UTF-8"?>
<robot xmlns:xacro="http://ros.org/wiki/xacro" name="linear_slider">

    <xacro:macro name="linear_slider_macro" params="prefix parent *origin">
        
        <!-- ================== -->
        <!--     Properties     -->
        <!-- ================== -->

        <!-- Model properties -->
        <xacro:property name="frame_mass" value="10.0"/>
        <xacro:property name="frame_length" value="1.25"/>
        <xacro:property name="frame_width" value="0.3"/>
        <xacro:property name="frame_height" value="0.25"/>

        <xacro:property name="moving_base_mass" value="10.0" />
        <xacro:property name="base_link_mass" value="20.0" />

        <!-- Model default position/orientation -->
        <xacro:property name="model_scale" value="0.001 0.001 0.001"/>
        <xacro:property name="base_link_start_orientation" value="0 0 0"/>
        <xacro:property name="moving_base_start_orientation" value="0 0 0"/>
        <xacro:property name="start_offset" value="0.0 0.0 0.0"/>

        <!-- Prismatic joint properties -->
        <xacro:property name="slider_limit_min" value="-0.4"/>
        <xacro:property name="slider_limit_max" value="0.4"/>
        <xacro:property name="slider_velocity_limit" value="0.25"/>
        <xacro:property name="slider_effort_limit" value="10"/>

        <!-- ================== -->
        <!--     Materials      -->
        <!-- ================== -->
        <material name="alpha_black">
            <color rgba="0.6 0.6 0.6 1"/>
        </material>
        <material name="red_v">
            <color rgba="1 0 0 1"/>
        </material>

        <!-- ================== -->
        <!--       Links        -->
        <!-- ================== -->
        <!-- base_link -->
        <link name="${prefix}base_link">
            <visual>
                <material name="alpha_black"/>
                <origin rpy="${base_link_start_orientation}" xyz="${start_offset}"/>
                <geometry>
                    <mesh filename="file://$(find linear_slider_description)/meshes/7thlink_fixed.STL" scale="${model_scale}" />
                </geometry>
            </visual>
            <collision>
                <geometry>
                    <box size="1.0 0.3 0.10"/>
                    <!-- <mesh
                        filename="package://linear_slider_description/meshes/7thlink_fixed.STL"
                        scale="${model_scale}"
                    /> -->
                </geometry>
            </collision>
            <inertial>
                <mass value="${base_link_mass}" />
                <origin xyz="0.0 0.0 0.0" />
                <inertia
                    ixx="${1*12/(frame_mass + base_link_mass) * (frame_width**2 + frame_height**2)}"
                    ixy="0.0"
                    ixz="0.0"
                    iyy="${1*12/(frame_mass + base_link_mass) * (frame_length**2 + frame_height**2)}"
                    iyz="0.0"
                    izz="${1*12/(frame_mass + base_link_mass) * (frame_width**2 + frame_length**2)}"
                />
            </inertial>
        </link>
        <gazebo reference="${prefix}base_link">
            <material>Gazebo/Gray</material>
        </gazebo>
        <!-- moving_base link -->
        <link name="${prefix}moving_base">
            <visual>
                <origin rpy="${moving_base_start_orientation}" xyz="${start_offset}" />
                <material name="red_v" />
                <geometry>
                    <mesh
                        filename="file://$(find linear_slider_description)/meshes/7thlink_move.STL"
                        scale="${model_scale}"
                    />
                </geometry>
            </visual>
            <collision>
                <geometry>
                    <box size="0.22 0.202 0.118"/>
                    <!-- <mesh
                        filename="package://linear_slider_description/meshes/7thlink_move.STL"
                        scale="${model_scale}"
                    /> -->
                </geometry>
            </collision>
            <inertial>
                <mass value="${moving_base_mass}" />
                <origin xyz="0.0 0.0 0.0" />
                <inertia
                    ixx="${1*12/(frame_mass + moving_base_mass) * (frame_width**2 + frame_height**2)}"
                    ixy="0.0"
                    ixz="0.0"
                    iyy="${1*12/(frame_mass + moving_base_mass) * (frame_length**2 + frame_height**2)}"
                    iyz="0.0"
                    izz="${1*12/(frame_mass + moving_base_mass) * (frame_width**2 + frame_length**2)}"
                />
            </inertial>
        </link>
        <gazebo reference="${prefix}moving_base">
            <material>Gazebo/Red</material>
        </gazebo>

        <!-- tool link -->
        <link name="${prefix}tool0" />
        <link name="${prefix}base" />
        <!-- Frame for mounting EEF models to a manipulator. x+ axis points forward (REP 103). -->
        <link name="${prefix}flange" />
        

        <!-- ================== -->
        <!--       Joints       -->
        <!-- ================== -->
        <!-- base_joint fixes base_link to the environment -->
        <joint name="${prefix}base_joint" type="fixed">
            <parent link="${parent}"/>
            <child link="${prefix}base_link"/>
            <xacro:insert_block name="origin"/>
        </joint>
        <!-- joint1 -->
        <joint name="${prefix}joint1" type="prismatic">
            <parent link="base_link"/>
            <child link="moving_base"/>
            <axis xyz="1 0 0"/>
            <limit 
                effort="${slider_effort_limit}"
                lower="${slider_limit_min}"
                upper="${slider_limit_max}"
                velocity="${slider_velocity_limit}"
            /> <!-- effort is attribute for enforcing maximum joint effort, between 0 and 100% -->
            <origin xyz="0.0 0.0 0.0" /> <!-- Define where the joint will be located, defined in terms of parent's reference frame -->
        </joint>
        <!-- Extra joints for ros-industrial standard compatability -->
        <!-- tool frame to fixed frame -->
        <joint name="${prefix}moving_base-tool0" type="fixed">
            <parent link="${prefix}moving_base"/>
            <child link="${prefix}tool0"/>
            <origin xyz="0 0 0" rpy="0 0 0" />   
        </joint>
        <joint name="${prefix}base_link-base_joint" type="fixed">
            <origin xyz="0 0 0" rpy="0 0 0" />
            <parent link="${prefix}base_link" />
            <child link="${prefix}base" />
        </joint>
    
        <joint name="${prefix}tool0-flange_joint" type="fixed">
            <origin xyz="0 0 0" rpy="0 0 0" />
            <parent link="${prefix}tool0" />
            <child link="${prefix}flange" />
        </joint>

    </xacro:macro>
</robot>