<?xml version="1.0" ?>
<!-- =================================================================================== -->
<!-- |    This document was autogenerated by xacro from linear_slider.urdf.xacro       | -->
<!-- |    EDITING THIS FILE BY HAND IS NOT RECOMMENDED                                 | -->
<!-- =================================================================================== -->
<robot name="linear_slider">
  <!-- <xacro:arg name="simulation_controllers" default="" /> -->
  <!-- World link -->
  <link name="world"/>
  <!-- ================== -->
  <!--     Properties     -->
  <!-- ================== -->
  <!-- ================== -->
  <!--     Materials      -->
  <!-- ================== -->
  <material name="alpha_black">
    <color rgba="0.6 0.6 0.6 1"/>
  </material>
  <material name="red_v">
    <color rgba="1 0 0 1"/>
  </material>
  <!-- ================== -->
  <!--       Links        -->
  <!-- ================== -->
  <!-- base_link -->
  <link name="base_link">
    <visual>
      <material name="alpha_black"/>
      <origin rpy="0 0 0" xyz="0.0 0.0 0.0"/>
      <geometry>
        <mesh filename="file:///home/main/ros2_ws/install/linear_slider_description/share/linear_slider_description/meshes/7thlink_fixed.STL" scale="0.001 0.001 0.001"/>
      </geometry>
    </visual>
    <collision>
      <geometry>
        <box size="1.0 0.3 0.10"/>
        <!-- <mesh
                        filename="package://linear_slider_description/meshes/7thlink_fixed.STL"
                        scale="${model_scale}"
                    /> -->
      </geometry>
    </collision>
    <inertial>
      <mass value="20.0"/>
      <origin xyz="0.0 0.0 0.0"/>
      <inertia ixx="0.061" ixy="0.0" ixz="0.0" iyy="0.65" iyz="0.0" izz="0.661"/>
    </inertial>
  </link>
  <gazebo reference="base_link">
    <material>Gazebo/Gray</material>
  </gazebo>
  <!-- moving_base link -->
  <link name="moving_base">
    <visual>
      <origin rpy="0 0 0" xyz="0.0 0.0 0.0"/>
      <material name="red_v"/>
      <geometry>
        <mesh filename="file:///home/main/ros2_ws/install/linear_slider_description/share/linear_slider_description/meshes/7thlink_move.STL" scale="0.001 0.001 0.001"/>
      </geometry>
    </visual>
    <collision>
      <geometry>
        <box size="0.22 0.202 0.118"/>
        <!-- <mesh
                        filename="package://linear_slider_description/meshes/7thlink_move.STL"
                        scale="${model_scale}"
                    /> -->
      </geometry>
    </collision>
    <inertial>
      <mass value="10.0"/>
      <origin xyz="0.0 0.0 0.0"/>
      <inertia ixx="0.0915" ixy="0.0" ixz="0.0" iyy="0.975" iyz="0.0" izz="0.9915"/>
    </inertial>
  </link>
  <gazebo reference="moving_base">
    <material>Gazebo/Red</material>
  </gazebo>
  <!-- tool link -->
  <link name="tool0"/>
  <link name="base"/>
  <!-- Frame for mounting EEF models to a manipulator. x+ axis points forward (REP 103). -->
  <link name="flange"/>
  <!-- ================== -->
  <!--       Joints       -->
  <!-- ================== -->
  <!-- base_joint fixes base_link to the environment -->
  <joint name="base_joint" type="fixed">
    <parent link="world"/>
    <child link="base_link"/>
    <origin rpy="0 0 0" xyz="0 0 0"/>
  </joint>
  <!-- joint1 -->
  <joint name="joint1" type="prismatic">
    <parent link="base_link"/>
    <child link="moving_base"/>
    <axis xyz="1 0 0"/>
    <limit effort="10" lower="-0.4" upper="0.4" velocity="0.25"/>
    <!-- effort is attribute for enforcing maximum joint effort, between 0 and 100% -->
    <origin xyz="0.0 0.0 0.0"/>
    <!-- Define where the joint will be located, defined in terms of parent's reference frame -->
  </joint>
  <!-- Extra joints for ros-industrial standard compatability -->
  <!-- tool frame to fixed frame -->
  <joint name="moving_base-tool0" type="fixed">
    <parent link="moving_base"/>
    <child link="tool0"/>
    <origin rpy="0 0 0" xyz="0 0 0"/>
  </joint>
  <joint name="base_link-base_joint" type="fixed">
    <origin rpy="0 0 0" xyz="0 0 0"/>
    <parent link="base_link"/>
    <child link="base"/>
  </joint>
  <joint name="tool0-flange_joint" type="fixed">
    <origin rpy="0 0 0" xyz="0 0 0"/>
    <parent link="tool0"/>
    <child link="flange"/>
  </joint>
  <!-- The caret ^ indicates to use the outer-scope property (with same name). The pipe | indicates to use the given fallback if the property is not defined in outer scope. -->
  <!-- ================== -->
  <!--    ros2_control    -->
  <!-- ================== -->
  <ros2_control name="linear_slider_ros2_control" type="system">
    <!-- Hardware -->
    <hardware>
      <plugin>mock_components/GenericSystem</plugin>
      <param name="mock_sensor_commands">True</param>
      <!-- <param name="device_name">linear_slider_device</param>
                <param name="joint_name">prismatic_joint</param>
                <param name="robot_ip">169.254.97.178</param> -->
    </hardware>
    <!-- Joints -->
    <joint name="joint1">
      <!-- Command interface -->
      <!-- <command_interface name="position">
                    <param name="min">-0.40</param>
                    <param name="max">0.40</param>
                </command_interface> -->
      <command_interface name="velocity">
        <param name="min">-0.1</param>
        <param name="max">0.1</param>
      </command_interface>
      <!-- State interface -->
      <state_interface name="position">
        <param name="initial_value">0.0</param>
      </state_interface>
      <state_interface name="velocity">
        <param name="initial_value">0.0</param>
      </state_interface>
    </joint>
    <!-- Sensors -->
    <!-- <sensor name="lim_switch_neg">
                <state_interface name="switch_val">
                    <param name="initial_value">${initial_state['lim_switch_neg']}</param>
                </state_interface>
                <param name="frame_id">${prefix}base_link</param>
            </sensor>
            <sensor name="lim_switch_pos">
                <state_interface name="switch_val">
                    <param name="initial_value">${initial_state['lim_switch_pos']}</param>
                </state_interface>
                <param name="frame_id">${prefix}base_link</param>
            </sensor> -->
  </ros2_control>
</robot>
