<?xml version="1.0" ?>
<!-- =================================================================================== -->
<!-- |    This document was autogenerated by xacro from /home/luke/ros2_ws/src/linear_slider_urdf/urdf/linear_slider_urdf.xacro | -->
<!-- |    EDITING THIS FILE BY HAND IS NOT RECOMMENDED                                 | -->
<!-- =================================================================================== -->
<robot name="linear_slider">
  <!-- ================== -->
  <!--     Properties     -->
  <!-- ================== -->
  <!-- ================== -->
  <!--     Materials      -->
  <!-- ================== -->
  <material name="alpha_black">
    <color rgba="0.6 0.6 0.6 1"/>
  </material>
  <material name="red_v">
    <color rgba="1 0 0 1"/>
  </material>
  <!-- ================== -->
  <!--       Links        -->
  <!-- ================== -->
  <link name="base_link">
    <visual>
      <material name="alpha_black"/>
      <origin rpy="0 0 0" xyz="0.0 0.0 0.0"/>
      <geometry>
        <mesh filename="package://linear-slider/linear_slider_description/meshes/7thlink_fixed.STL"
          scale="0.001 0.001 0.001" />
      </geometry>
    </visual>
  </link>
  <link name="ls_moving_base">
    <visual>
      <origin rpy="0 0 0" xyz="0.0 0.0 0.0"/>
      <material name="red_v"/>
      <geometry>
        <mesh filename="package://linear-slider/linear_slider_description/meshes/7thlink_move.STL"
          scale="0.001 0.001 0.001" />
      </geometry>
    </visual>
    <collision>
      <geometry>
        <mesh filename="package://linear-slider/linear_slider_description/meshes/7thlink_move.STL"
          scale="0.001 0.001 0.001" />
      </geometry>
    </collision>
    <inertial>
      <mass value="10.0"/>
      <origin xyz="0.0 0.0 0.0"/>
      <inertia ixx="0.0915" ixy="0.0" ixz="0.0" iyy="0.975" iyz="0.0" izz="0.9915"/>
    </inertial>
  </link>
  <joint name="ls_base_link_ls_moving_base_joint" type="prismatic">
    <parent link="base_link"/>
    <child link="ls_moving_base"/>
    <axis xyz="1 0 0"/>
    <limit effort="10" lower="-0.4" upper="0.4" velocity="0.25"/>
    <!-- effort is attribute for enforcing maximum joint effort, between 0 and 100% -->
    <origin xyz="0.0 0.0 0.0"/>
    <!-- Define where the joint will be located, defined in terms of parent's reference frame -->
  </joint>
</robot>
