<?xml version="1.0" ?>
<!-- =================================================================================== -->
<!-- |    This document was autogenerated by xacro from linear_slider.urdf.xacro       | -->
<!-- |    EDITING THIS FILE BY HAND IS NOT RECOMMENDED                                 | -->
<!-- =================================================================================== -->
<robot name="linear_slider">
  <!-- ================== -->
  <!--     Properties     -->
  <!-- ================== -->
  <!-- ================== -->
  <!--     Materials      -->
  <!-- ================== -->
  <material name="alpha_black">
    <color rgba="0.6 0.6 0.6 1"/>
  </material>
  <material name="red_v">
    <color rgba="1 0 0 1"/>
  </material>
  <!-- ================== -->
  <!--       Links        -->
  <!-- ================== -->
  <!-- <link name="world" /> -->
  <link name="base_link">
    <visual>
      <material name="alpha_black"/>
      <origin rpy="0 0 0" xyz="0.0 0.0 0.0"/>
      <geometry>
        <mesh filename="package://linear_slider_description/meshes/7thlink_fixed.STL" scale="0.001 0.001 0.001"/>
      </geometry>
    </visual>
    <collision>
      <geometry>
        <!-- <box size="0.22 0.202 0.118"/> -->
        <mesh filename="package://linear_slider_description/meshes/7thlink_fixed.STL" scale="0.001 0.001 0.001"/>
      </geometry>
    </collision>
  </link>
  <link name="moving_base">
    <visual>
      <origin rpy="0 0 0" xyz="0.0 0.0 0.0"/>
      <material name="red_v"/>
      <geometry>
        <mesh filename="package://linear_slider_description/meshes/7thlink_move.STL" scale="0.001 0.001 0.001"/>
      </geometry>
    </visual>
    <collision>
      <geometry>
        <mesh filename="package://linear_slider_description/meshes/7thlink_move.STL" scale="0.001 0.001 0.001"/>
      </geometry>
    </collision>
    <inertial>
      <mass value="10.0"/>
      <origin xyz="0.0 0.0 0.0"/>
      <inertia ixx="0.0915" ixy="0.0" ixz="0.0" iyy="0.975" iyz="0.0" izz="0.9915"/>
    </inertial>
  </link>
  <joint name="joint1" type="prismatic">
    <parent link="base_link"/>
    <child link="moving_base"/>
    <axis xyz="1 0 0"/>
    <limit effort="10" lower="-0.4" upper="0.4" velocity="0.25"/>
    <!-- effort is attribute for enforcing maximum joint effort, between 0 and 100% -->
    <origin xyz="0.0 0.0 0.0"/>
    <!-- Define where the joint will be located, defined in terms of parent's reference frame -->
  </joint>
  <ros2_control name="linear_slider" type="system">
    <!-- Hardware -->
    <hardware>
      <plugin>linear_slider_hardware_interface/LinearSliderHardwareInterface</plugin>
      <!-- <plugin>linear_slider_system_interface/LinearSliderSystemInterface</plugin> -->
      <param name="device_name">linear_slider_ros2_control</param>
      <param name="joint_name">prismatic_joint</param>
      <param name="robot_ip">169.254.97.178</param>
      <!-- <plugin>gz_ros2_control/GazeboSimSystem</plugin> -->
    </hardware>
    <!-- Joints -->
    <joint name="joint1">
      <!-- Command interface -->
      <command_interface name="position">
        <param name="min">-0.40</param>
        <param name="max">0.40</param>
      </command_interface>
      <command_interface name="velocity">
        <param name="min">-0.1</param>
        <param name="max">0.1</param>
      </command_interface>
      <!-- State interface -->
      <state_interface name="position">
        <param name="initial_value">0.0</param>
      </state_interface>
      <state_interface name="velocity">
        <param name="initial_value">0.0</param>
      </state_interface>
    </joint>
    <!-- Sensors -->
    <sensor name="lim_switch_neg">
      <state_interface name="switch_val">
        <param name="initial_value">False</param>
      </state_interface>
    </sensor>
    <sensor name="lim_switch_pos">
      <state_interface name="swtich_val">
        <param name="initial_value">False</param>
      </state_interface>
    </sensor>
  </ros2_control>
  <gazebo>
    <plugin filename="libgazebo_ros2_control.so" name="gazebo_ros2_control">
      <robot_param>robot_description</robot_param>
      <robot_param_node>robot_state_publisher</robot_param_node>
      <parameters>/home/luke/ros2_ws/install/linear_slider_bringup/share/linear_slider_bringup/config/linear_slider_controllers.yaml</parameters>
    </plugin>
  </gazebo>
</robot>
